<mujoco model="go2">
  <compiler angle="radian" meshdir="assets" autolimits="true" />

  <option cone="elliptic" impratio="100" />

  <default>
    <default class="go2">
      <geom friction="1.5 0.05 0.01" margin="0.001" condim="3" solimp="0.95 0.99 0.0001" solref="0.002 1"/>
      <joint axis="0 1 0" damping="0.3" armature="0.01" frictionloss="0.2"/>
      
      <position kp="100" kv="5.0" forcelimited="true" forcerange="-23.7 23.7"/>
      
      <default class="abduction">
        <joint axis="0 1 0" range="0 0"/>
      </default>
      <default class="hip">
        <default class="front_hip">
          <joint range="-0.5236 4.5379"/>#-1.5708 3.4907
        </default>
        <default class="back_hip">
          <joint range="-0.5236 4.5379"/>
        </default>
      </default>
      <default class="knee">
        <joint range="-2.7227 -0.83776"/>
        <position kp="100" kv="5.0" forcerange="-23.7 23.7"/>
      </default>
      
      <default class="visual">
        <geom type="mesh" contype="0" conaffinity="0" group="2"/>
      </default>
      <default class="collision">
        <geom group="3"/>
        <default class="foot">
          <geom size="0.022" pos="-0.002 0 -0.213" priority="1" condim="6" friction="1.5 0.05 0.01"/>
        </default>
      </default>
    </default>
  </default>

  <asset>
    <material name="metal" rgba=".9 .95 .95 1" />
    <material name="black" rgba="0 0 0 1" />
    <material name="white" rgba="1 1 1 1" />
    <material name="gray" rgba="0.671705 0.692426 0.774270 1" />

    <mesh file="base_0.obj" />
    <mesh file="base_1.obj" />
    <mesh file="base_2.obj" />
    <mesh file="base_3.obj" />
    <mesh file="base_4.obj" />
    <mesh file="hip_0.obj" />
    <mesh file="hip_1.obj" />
    <mesh file="thigh_0.obj" />
    <mesh file="thigh_1.obj" />
    <mesh file="thigh_mirror_0.obj" />
    <mesh file="thigh_mirror_1.obj" />
    <mesh file="calf_0.obj" />
    <mesh file="calf_1.obj" />
    <mesh file="calf_mirror_0.obj" />
    <mesh file="calf_mirror_1.obj" />
    <mesh file="foot.obj" />
  </asset>

  <worldbody>
    <body name="base_link" pos="0 0 0.4" childclass="go2">
      <inertial pos="0.05 0 -0.05366" quat="-0.000543471 0.713435 -0.00173769 0.700719"
        mass="8.0"
        diaginertia="0.107027 0.0980771 0.0244531" />
      <freejoint />
      <geom mesh="base_0" material="black" class="visual" />
      <geom mesh="base_1" material="black" class="visual" />
      <geom mesh="base_2" material="black" class="visual" />
      <geom mesh="base_3" material="white" class="visual" />
      <geom mesh="base_4" material="gray" class="visual" />
      <geom size="0.1881 0.04675 0.057" type="box" class="collision" />
      <geom size="0.05 0.045" pos="0.285 0 0.01" type="cylinder" class="collision" />
      <geom size="0.047" pos="0.293 0 -0.06" class="collision" />
      <site name="imu" pos="-0.02557 0 0.04232" />

      <body name="FL_hip" pos="0.1934 0.0465 0">
        <joint name="FL_hip_joint" class="abduction" />
        <geom mesh="hip_0" material="metal" class="visual" />
        <body name="FL_thigh" pos="0.0 0.0955 0">
          <joint name="FL_thigh_joint" class="hip" />
          <geom mesh="thigh_0" material="metal" class="visual" />
          <body name="FL_calf" pos="0 0 -0.213">
            <joint name="FL_calf_joint" class="knee" />
            <geom mesh="calf_0" material="gray" class="visual" />
            <geom pos="0 0 -0.213" mesh="foot" class="visual" material="black" />
            <geom name="FL" class="foot" />
          </body>
        </body>
      </body>

      <body name="FR_hip" pos="0.1934 -0.0465 0">
        <joint name="FR_hip_joint" class="abduction" />
        <geom mesh="hip_0" material="metal" class="visual" quat="0 1 0 0" />
        <body name="FR_thigh" pos="0.0 -0.0955 0">
          <joint name="FR_thigh_joint" class="hip" />
          <geom mesh="thigh_mirror_0" material="metal" class="visual" />
          <body name="FR_calf" pos="0 0 -0.213">
            <joint name="FR_calf_joint" class="knee" />
            <geom mesh="calf_mirror_0" material="gray" class="visual" />
            <geom pos="0 0 -0.213" mesh="foot" class="visual" material="black" />
            <geom name="FR" class="foot" />
          </body>
        </body>
      </body>

      <body name="RL_hip" pos="-0.1934 0.0465 0">
        <joint name="RL_hip_joint" class="abduction" />
        <geom mesh="hip_0" material="metal" class="visual" quat="0 0 1 0" />
        <body name="RL_thigh" pos="0.0 0.0955 0">
          <joint name="RL_thigh_joint" class="hip" />
          <geom mesh="thigh_0" material="metal" class="visual" />
          <body name="RL_calf" pos="0 0 -0.213">
            <joint name="RL_calf_joint" class="knee" />
            <geom mesh="calf_0" material="gray" class="visual" />
            <geom pos="0 0 -0.213" mesh="foot" class="visual" material="black" />
            <geom name="RL" class="foot" />
          </body>
        </body>
      </body>

      <body name="RR_hip" pos="-0.1934 -0.0465 0">
        <joint name="RR_hip_joint" class="abduction" />
        <geom mesh="hip_0" material="metal" class="visual" quat="0 0 0 1" />
        <body name="RR_thigh" pos="0.0 -0.0955 0">
          <joint name="RR_thigh_joint" class="hip" />
          <geom mesh="thigh_mirror_0" material="metal" class="visual" />
          <body name="RR_calf" pos="0 0 -0.213">
            <joint name="RR_calf_joint" class="knee" />
            <geom mesh="calf_mirror_0" material="gray" class="visual" />
            <geom pos="0 0 -0.213" mesh="foot" class="visual" material="black" />
            <geom name="RR" class="foot" />
          </body>
        </body>
      </body>
    </body>
  </worldbody>

  <actuator>
    <position name="FR_hip" joint="FR_hip_joint" class="abduction"/>
    <position name="FR_thigh" joint="FR_thigh_joint" class="hip"/>
    <position name="FR_calf" joint="FR_calf_joint" class="knee"/>
    <position name="FL_hip" joint="FL_hip_joint" class="abduction"/>
    <position name="FL_thigh" joint="FL_thigh_joint" class="hip"/>
    <position name="FL_calf" joint="FL_calf_joint" class="knee"/>
    <position name="RR_hip" joint="RR_hip_joint" class="abduction"/>
    <position name="RR_thigh" joint="RR_thigh_joint" class="hip"/>
    <position name="RR_calf" joint="RR_calf_joint" class="knee"/>
    <position name="RL_hip" joint="RL_hip_joint" class="abduction"/>
    <position name="RL_thigh" joint="RL_thigh_joint" class="hip"/>
    <position name="RL_calf" joint="RL_calf_joint" class="knee"/>
  </actuator>

  <sensor>
    <gyro name="imu_gyro" site="imu" />
    <framequat name="imu_quat" objtype="site" objname="imu" />
    <framelinvel name="frame_vel" objtype="site" objname="imu" />
  </sensor>

  <keyframe>
    <key name="home" 
        qpos="0 0 0.35 1 0 0 0 -0.1 0.8 -1.2 0.1 0.8 -1.2 -0.1 0.8 -1.2 0.1 0.8 -1.2"
        ctrl="-0.1 0.8 -1.2 0.1 0.8 -1.2 -0.1 0.8 -1.2 0.1 0.8 -1.2" />
  </keyframe>
</mujoco>